Workbook

Sheet Assumptions
A1: Executive Edge OS — Financial Model · Assumptions
A2: ALL FIGURES ARE ASSUMPTIONS to confirm live (April pricing docs are stale per venture context). Blue = input you edit · Green = link from another sheet · Black = formula · Yellow = key sensitivity. Not licensed tax/accounting advice — CPA/controller review flagged throughout.
A4: PRICING ($)
A5: Subscription (per month) | B5: 99
A6: Unlock (one-time) | B6: 199
A7: Flagship program (one-time) | B7: 4997
A8: Private client (per month, capped) | B8: 1750
A9: Cohort contract value (6-mo, B2B) | B9: 36000 | C9: floor $30k; collected upfront → DEFERRED
A10: Cohort term (months) | B10: 6
A11: License setup (one-time) | B11: 15000
A12: License recurring (per month) | B12: 1500
A14: SUBSCRIPTION VOLUME & GROWTH
A15: Starting active subscribers | B15: 40
A16: New subs / month (M1) | B16: 15
A17: New-sub monthly growth | B17: 0.08
A18: Monthly subscriber churn | B18: 0.05
A19: Unlocks / month (M1) | B19: 25
A20: Unlock monthly growth | B20: 0.05
A21: Flagship sales / month | B21: 1
A22: Active private clients | B22: 3
A24: COGS RATES
A25: Hosting / infra (per month) | B25: 1500
A26: AI / API base (per month) | B26: 400
A27: AI / API per active sub (per month) | B27: 2
A28: Payment processing (% of revenue) | B28: 0.03
A29: High-touch delivery labor (% B2B/flagship/private) | B29: 0.3
A30: Labs / data (% of clinical revenue) | B30: 0.06
A32: OPERATING EXPENSES (per month, $)
A33: Payroll & wages | B33: 6000
A34: Contractors | B34: 3000
A35: Software / tools | B35: 1200
A36: Marketing / ads (test only — $0 until proven) | B36: 0 | C36: guardrail: $0 on unvalidated; no spend w/o approval
A37: Professional fees (legal / CPA) | B37: 1500
A38: Bank / card fees | B38: 150
A39: Insurance | B39: 300
A40: G&A / admin | B40: 500
A42: CASH & TAX
A43: Starting cash | B43: 120000
A44: Tax reserve (% of net income) | B44: 0.21 | C44: illustrative — needs CPA (entity/jurisdiction)

Sheet UnitEconomics
A1: Unit Economics — anchor lines (pulled from /offer-architect)
A2: Economics are consumed from /offer-architect, not re-derived. Blue = CAC assumption to confirm.
A4: B2C SUBSCRIPTION
A5: Price / month | B5: =Assumptions!$B$5 -> 99
A6: Gross margin % (blended) | B6: =1-Assumptions!$B$28-Assumptions!$B$30-(Assumptions!$B$27/Assumptions!$B$5) -> 0.88979798
A7: Gross profit / month | B7: =B5*B6 -> 88.09
A8: Monthly churn | B8: =Assumptions!$B$18 -> 0.05
A9: Avg customer lifetime (months) | B9: =1/B8 -> 20
A10: LTV (gross-profit basis) | B10: =B7*B9 -> 1761.8
A11: CAC (assumption) | B11: 250
A12: CAC payback (months) | B12: =B11/B7 -> 2.8380066
A13: LTV : CAC | B13: =B10/B11 -> 7.0472
A15: B2B CORPORATE COHORT
A16: Contract value (6-mo) | B16: =Assumptions!$B$9 -> 36000
A17: Term (months) | B17: =Assumptions!$B$10 -> 6
A18: Delivery labor % (manual quarterly report) | B18: =Assumptions!$B$29 -> 0.3
A19: Gross margin % | B19: =1-B18-Assumptions!$B$28 -> 0.67
A20: Gross profit / contract | B20: =B16*B19 -> 24120
A21: Sales cost / deal (CAC, assumption) | B21: 2000
A22: Gross profit : CAC | B22: =B20/B21 -> 12.06
A23: Monthly recognized revenue (deferred) | B23: =B16/B17 -> 6000
A25: Most-sensitive drivers: B2B cohort close rate + subscriber churn (protect these).

Sheet PnL
A1: Executive Edge OS — 12-Month P&L (driver-based, accrual)
A3: ($, monthly) | B3: M1 | C3: M2 | D3: M3 | E3: M4 | F3: M5 | G3: M6 | H3: M7 | I3: M8 | J3: M9 | K3: M10 | L3: M11 | M3: M12 | N3: Year 1
A5: VOLUME (drivers)
A6: Active subs — BOP | B6: =Assumptions!$B$15 -> 40 | C6: =B9 -> 53 | D6: =C9 -> 66.55 | E6: =D9 -> 80.7185 | F6: =E9 -> 95.578255 | G6: =F9 -> 111.20668 | H6: =G9 -> 127.68626 | I6: =H9 -> 145.10507 | J6: =I9 -> 163.55718 | ... M6: =L9 -> 226.15649
A7: New subs | B7: =Assumptions!$B$16 -> 15 | C7: =B7*(1+Assumptions!$B$17) -> 16.2 | D7: =C7*(1+Assumptions!$B$17) -> 17.496 | E7: =D7*(1+Assumptions!$B$17) -> 18.89568 | F7: =E7*(1+Assumptions!$B$17) -> 20.407334 | G7: =F7*(1+Assumptions!$B$17) -> 22.039921 | H7: =G7*(1+Assumptions!$B$17) -> 23.803115 | I7: =H7*(1+Assumptions!$B$17) -> 25.707364 | J7: =I7*(1+Assumptions!$B$17) -> 27.763953 | ... M7: =L7*(1+Assumptions!$B$17) -> 34.974585
A8: Churned subs | B8: =B6*Assumptions!$B$18 -> 2 | C8: =C6*Assumptions!$B$18 -> 2.65 | D8: =D6*Assumptions!$B$18 -> 3.3275 | E8: =E6*Assumptions!$B$18 -> 4.035925 | F8: =F6*Assumptions!$B$18 -> 4.7789127 | G8: =G6*Assumptions!$B$18 -> 5.5603338 | H8: =H6*Assumptions!$B$18 -> 6.3843132 | I8: =I6*Assumptions!$B$18 -> 7.2552533 | ... M8: =M6*Assumptions!$B$18 -> 11.307825
A9: Active subs — EOP | B9: =B6+B7-B8 -> 53 | C9: =C6+C7-C8 -> 66.55 | D9: =D6+D7-D8 -> 80.7185 | E9: =E6+E7-E8 -> 95.578255 | F9: =F6+F7-F8 -> 111.20668 | G9: =G6+G7-G8 -> 127.68626 | H9: =H6+H7-H8 -> 145.10507 | I9: =I6+I7-I8 -> 163.55718 | ... M9: =M6+M7-M8 -> 249.82325
A10: Unlocks (units) | B10: =Assumptions!$B$19 -> 25 | C10: =B10*(1+Assumptions!$B$20) -> 26.25 | D10: =C10*(1+Assumptions!$B$20) -> 27.5625 | E10: =D10*(1+Assumptions!$B$20) -> 28.940625 | F10: =E10*(1+Assumptions!$B$20) -> 30.387656 | G10: =F10*(1+Assumptions!$B$20) -> 31.907039 | H10: =G10*(1+Assumptions!$B$20) -> 33.502391 | I10: =H10*(1+Assumptions!$B$20) -> 35.177511 | J10: =I10*(1+Assumptions!$B$20) -> 36.936386 | ... M10: =L10*(1+Assumptions!$B$20) -> 42.758484
A11: Flagship sales (units) | B11: =Assumptions!$B$21 -> 1 | C11: =Assumptions!$B$21 -> 1 | D11: =Assumptions!$B$21 -> 1 | E11: =Assumptions!$B$21 -> 1 | F11: =Assumptions!$B$21 -> 1 | G11: =Assumptions!$B$21 -> 1 | H11: =Assumptions!$B$21 -> 1 | I11: =Assumptions!$B$21 -> 1 | ... M11: =Assumptions!$B$21 -> 1
A12: Active private clients | B12: =Assumptions!$B$22 -> 3 | C12: =Assumptions!$B$22 -> 3 | D12: =Assumptions!$B$22 -> 3 | E12: =Assumptions!$B$22 -> 3 | F12: =Assumptions!$B$22 -> 3 | G12: =Assumptions!$B$22 -> 3 | H12: =Assumptions!$B$22 -> 3 | I12: =Assumptions!$B$22 -> 3 | ... M12: =Assumptions!$B$22 -> 3
A13: New cohorts started (input) | B13: 0 | C13: 1 | D13: 1 | E13: 1 | F13: 2 | G13: 2 | H13: 2 | I13: 2 | J13: 2 | K13: 2 | L13: 2 | M13: 2
A14: Active cohorts (6-mo rev window) | B14: =SUM(B13:B13) -> 0 | C14: =SUM(B13:C13) -> 1 | D14: =SUM(B13:D13) -> 2 | E14: =SUM(B13:E13) -> 3 | F14: =SUM(B13:F13) -> 5 | G14: =SUM(B13:G13) -> 7 | H14: =SUM(C13:H13) -> 9 | I14: =SUM(D13:I13) -> 10 | J14: =SUM(E13:J13) -> 11 | K14: =SUM(F13:K13) -> 12 | L14: =SUM(G13:L13) -> 12 | M14: =SUM(H13:M13) -> 12
A15: New licenses started (input) | B15: 0 | C15: 0 | D15: 1 | E15: 0 | F15: 1 | G15: 0 | H15: 1 | I15: 0 | J15: 1 | K15: 0 | L15: 1 | M15: 1
A16: Active licenses (cumulative) | B16: =SUM($B15:B15) -> 0 | C16: =SUM($B15:C15) -> 0 | D16: =SUM($B15:D15) -> 1 | E16: =SUM($B15:E15) -> 1 | F16: =SUM($B15:F15) -> 2 | G16: =SUM($B15:G15) -> 2 | H16: =SUM($B15:H15) -> 3 | I16: =SUM($B15:I15) -> 3 | ... M16: =SUM($B15:M15) -> 6
A18: REVENUE
A19: Subscription | B19: =(B6+B9)/2*Assumptions!$B$5 -> 4603.5 | C19: =(C6+C9)/2*Assumptions!$B$5 -> 5917.725 | D19: =(D6+D9)/2*Assumptions!$B$5 -> 7289.7908 | E19: =(E6+E9)/2*Assumptions!$B$5 -> 8726.6894 | F19: =(F6+F9)/2*Assumptions!$B$5 -> 10235.854 | G19: =(G6+G9)/2*Assumptions!$B$5 -> 11825.201 | H19: =(H6+H9)/2*Assumptions!$B$5 -> 13503.171 | I19: =(I6+I9)/2*Assumptions!$B$5 -> 15278.781 | ... M19: =(M6+M9)/2*Assumptions!$B$5 -> 23560.997 | N19: =SUM(B19:M19) -> 158556.87
A20: Unlock (one-time) | B20: =B10*Assumptions!$B$6 -> 4975 | C20: =C10*Assumptions!$B$6 -> 5223.75 | D20: =D10*Assumptions!$B$6 -> 5484.9375 | E20: =E10*Assumptions!$B$6 -> 5759.1844 | F20: =F10*Assumptions!$B$6 -> 6047.1436 | G20: =G10*Assumptions!$B$6 -> 6349.5008 | H20: =H10*Assumptions!$B$6 -> 6666.9758 | I20: =I10*Assumptions!$B$6 -> 7000.3246 | ... M20: =M10*Assumptions!$B$6 -> 8508.9383 | N20: =SUM(B20:M20) -> 79187.704
A21: Flagship | B21: =B11*Assumptions!$B$7 -> 4997 | C21: =C11*Assumptions!$B$7 -> 4997 | D21: =D11*Assumptions!$B$7 -> 4997 | E21: =E11*Assumptions!$B$7 -> 4997 | F21: =F11*Assumptions!$B$7 -> 4997 | G21: =G11*Assumptions!$B$7 -> 4997 | H21: =H11*Assumptions!$B$7 -> 4997 | I21: =I11*Assumptions!$B$7 -> 4997 | ... M21: =M11*Assumptions!$B$7 -> 4997 | N21: =SUM(B21:M21) -> 59964
A22: Private client | B22: =B12*Assumptions!$B$8 -> 5250 | C22: =C12*Assumptions!$B$8 -> 5250 | D22: =D12*Assumptions!$B$8 -> 5250 | E22: =E12*Assumptions!$B$8 -> 5250 | F22: =F12*Assumptions!$B$8 -> 5250 | G22: =G12*Assumptions!$B$8 -> 5250 | H22: =H12*Assumptions!$B$8 -> 5250 | I22: =I12*Assumptions!$B$8 -> 5250 | ... M22: =M12*Assumptions!$B$8 -> 5250 | N22: =SUM(B22:M22) -> 63000
A23: Cohort (recognized, deferred) | B23: =B14*Assumptions!$B$9/Assumptions!$B$10 -> 0 | C23: =C14*Assumptions!$B$9/Assumptions!$B$10 -> 6000 | D23: =D14*Assumptions!$B$9/Assumptions!$B$10 -> 12000 | E23: =E14*Assumptions!$B$9/Assumptions!$B$10 -> 18000 | F23: =F14*Assumptions!$B$9/Assumptions!$B$10 -> 30000 | G23: =G14*Assumptions!$B$9/Assumptions!$B$10 -> 42000 | H23: =H14*Assumptions!$B$9/Assumptions!$B$10 -> 54000 | I23: =I14*Assumptions!$B$9/Assumptions!$B$10 -> 60000 | ... M23: =M14*Assumptions!$B$9/Assumptions!$B$10 -> 72000 | N23: =SUM(B23:M23) -> 504000
A24: License setup | B24: =B15*Assumptions!$B$11 -> 0 | C24: =C15*Assumptions!$B$11 -> 0 | D24: =D15*Assumptions!$B$11 -> 15000 | E24: =E15*Assumptions!$B$11 -> 0 | F24: =F15*Assumptions!$B$11 -> 15000 | G24: =G15*Assumptions!$B$11 -> 0 | H24: =H15*Assumptions!$B$11 -> 15000 | I24: =I15*Assumptions!$B$11 -> 0 | ... M24: =M15*Assumptions!$B$11 -> 15000 | N24: =SUM(B24:M24) -> 90000
A25: License recurring | B25: =B16*Assumptions!$B$12 -> 0 | C25: =C16*Assumptions!$B$12 -> 0 | D25: =D16*Assumptions!$B$12 -> 1500 | E25: =E16*Assumptions!$B$12 -> 1500 | F25: =F16*Assumptions!$B$12 -> 3000 | G25: =G16*Assumptions!$B$12 -> 3000 | H25: =H16*Assumptions!$B$12 -> 4500 | I25: =I16*Assumptions!$B$12 -> 4500 | ... M25: =M16*Assumptions!$B$12 -> 9000 | N25: =SUM(B25:M25) -> 46500
A26: Total revenue | B26: =SUM(B19:B25) -> 19825.5 | C26: =SUM(C19:C25) -> 27388.475 | D26: =SUM(D19:D25) -> 51521.728 | E26: =SUM(E19:E25) -> 44232.874 | F26: =SUM(F19:F25) -> 74529.998 | G26: =SUM(G19:G25) -> 73421.701 | H26: =SUM(H19:H25) -> 103917.15 | I26: =SUM(I19:I25) -> 97026.106 | ... M26: =SUM(M19:M25) -> 138316.94 | N26: =SUM(B26:M26) -> 1001208.6
A28: COST OF GOODS SOLD
A29: Hosting / infra | B29: =Assumptions!$B$25 -> 1500 | C29: =Assumptions!$B$25 -> 1500 | D29: =Assumptions!$B$25 -> 1500 | E29: =Assumptions!$B$25 -> 1500 | F29: =Assumptions!$B$25 -> 1500 | G29: =Assumptions!$B$25 -> 1500 | H29: =Assumptions!$B$25 -> 1500 | I29: =Assumptions!$B$25 -> 1500 | ... M29: =Assumptions!$B$25 -> 1500 | N29: =SUM(B29:M29) -> 18000
A30: AI / API | B30: =Assumptions!$B$26+B9*Assumptions!$B$27 -> 506 | C30: =Assumptions!$B$26+C9*Assumptions!$B$27 -> 533.1 | D30: =Assumptions!$B$26+D9*Assumptions!$B$27 -> 561.437 | E30: =Assumptions!$B$26+E9*Assumptions!$B$27 -> 591.15651 | F30: =Assumptions!$B$26+F9*Assumptions!$B$27 -> 622.41335 | G30: =Assumptions!$B$26+G9*Assumptions!$B$27 -> 655.37253 | H30: =Assumptions!$B$26+H9*Assumptions!$B$27 -> 690.21013 | I30: =Assumptions!$B$26+I9*Assumptions!$B$27 -> 727.11435 | ... M30: =Assumptions!$B$26+M9*Assumptions!$B$27 -> 899.64651 | N30: =SUM(B30:M30) -> 8212.9923
A31: Payment processing | B31: =B26*Assumptions!$B$28 -> 594.765 | C31: =C26*Assumptions!$B$28 -> 821.65425 | D31: =D26*Assumptions!$B$28 -> 1545.6518 | E31: =E26*Assumptions!$B$28 -> 1326.9862 | F31: =F26*Assumptions!$B$28 -> 2235.8999 | G31: =G26*Assumptions!$B$28 -> 2202.651 | H31: =H26*Assumptions!$B$28 -> 3117.5144 | I31: =I26*Assumptions!$B$28 -> 2910.7832 | ... M31: =M26*Assumptions!$B$28 -> 4149.5081 | N31: =SUM(B31:M31) -> 30036.257
A32: Delivery labor (high-touch) | B32: =(B21+B22+B23+B24+B25)*Assumptions!$B$29 -> 3074.1 | C32: =(C21+C22+C23+C24+C25)*Assumptions!$B$29 -> 4874.1 | D32: =(D21+D22+D23+D24+D25)*Assumptions!$B$29 -> 11624.1 | E32: =(E21+E22+E23+E24+E25)*Assumptions!$B$29 -> 8924.1 | F32: =(F21+F22+F23+F24+F25)*Assumptions!$B$29 -> 17474.1 | G32: =(G21+G22+G23+G24+G25)*Assumptions!$B$29 -> 16574.1 | H32: =(H21+H22+H23+H24+H25)*Assumptions!$B$29 -> 25124.1 | I32: =(I21+I22+I23+I24+I25)*Assumptions!$B$29 -> 22424.1 | ... M32: =(M21+M22+M23+M24+M25)*Assumptions!$B$29 -> 31874.1 | N32: =SUM(B32:M32) -> 229039.2
A33: Labs / data | B33: =(B19+B20+B21+B23)*Assumptions!$B$30 -> 874.53 | C33: =(C19+C20+C21+C23)*Assumptions!$B$30 -> 1328.3085 | D33: =(D19+D20+D21+D23)*Assumptions!$B$30 -> 1786.3037 | E33: =(E19+E20+E21+E23)*Assumptions!$B$30 -> 2248.9724 | F33: =(F19+F20+F21+F23)*Assumptions!$B$30 -> 3076.7999 | G33: =(G19+G20+G21+G23)*Assumptions!$B$30 -> 3910.3021 | H33: =(H19+H20+H21+H23)*Assumptions!$B$30 -> 4750.0288 | I33: =(I19+I20+I21+I23)*Assumptions!$B$30 -> 5236.5663 | ... M33: =(M19+M20+M21+M23)*Assumptions!$B$30 -> 6544.0161 | N33: =SUM(B33:M33) -> 48102.514
A34: Total COGS | B34: =SUM(B29:B33) -> 6549.395 | C34: =SUM(C29:C33) -> 9057.1627 | D34: =SUM(D29:D33) -> 17017.493 | E34: =SUM(E29:E33) -> 14591.215 | F34: =SUM(F29:F33) -> 24909.213 | G34: =SUM(G29:G33) -> 24842.426 | H34: =SUM(H29:H33) -> 35181.853 | I34: =SUM(I29:I33) -> 32798.564 | ... M34: =SUM(M29:M33) -> 44967.271 | N34: =SUM(B34:M34) -> 333390.96
A35: Gross profit | B35: =B26-B34 -> 13276.105 | C35: =C26-C34 -> 18331.312 | D35: =D26-D34 -> 34504.236 | E35: =E26-E34 -> 29641.659 | F35: =F26-F34 -> 49620.785 | G35: =G26-G34 -> 48579.276 | H35: =H26-H34 -> 68735.293 | I35: =I26-I34 -> 64227.542 | ... N35: =N26-N34 -> 667817.61
A36: Gross margin % | B36: =IF(B26=0,0,B35/B26) -> 0.66964793 | C36: =IF(C26=0,0,C35/C26) -> 0.66930752 | D36: =IF(D26=0,0,D35/D26) -> 0.66970261 | E36: =IF(E26=0,0,E35/E26) -> 0.67012735 | F36: =IF(F26=0,0,F35/F26) -> 0.66578272 | G36: =IF(G26=0,0,G35/G26) -> 0.66164737 | H36: =IF(H26=0,0,H35/H26) -> 0.66144323 | I36: =IF(I26=0,0,I35/I26) -> 0.66196145 | ... N36: =IF(N26=0,0,N35/N26) -> 0.66701148
A38: OPERATING EXPENSES
A39: Payroll & wages | B39: =Assumptions!$B$33 -> 6000 | C39: =Assumptions!$B$33 -> 6000 | D39: =Assumptions!$B$33 -> 6000 | E39: =Assumptions!$B$33 -> 6000 | F39: =Assumptions!$B$33 -> 6000 | G39: =Assumptions!$B$33 -> 6000 | H39: =Assumptions!$B$33 -> 6000 | I39: =Assumptions!$B$33 -> 6000 | ... M39: =Assumptions!$B$33 -> 6000 | N39: =SUM(B39:M39) -> 72000
A40: Contractors | B40: =Assumptions!$B$34 -> 3000 | C40: =Assumptions!$B$34 -> 3000 | D40: =Assumptions!$B$34 -> 3000 | E40: =Assumptions!$B$34 -> 3000 | F40: =Assumptions!$B$34 -> 3000 | G40: =Assumptions!$B$34 -> 3000 | H40: =Assumptions!$B$34 -> 3000 | I40: =Assumptions!$B$34 -> 3000 | ... M40: =Assumptions!$B$34 -> 3000 | N40: =SUM(B40:M40) -> 36000
A41: Software / tools | B41: =Assumptions!$B$35 -> 1200 | C41: =Assumptions!$B$35 -> 1200 | D41: =Assumptions!$B$35 -> 1200 | E41: =Assumptions!$B$35 -> 1200 | F41: =Assumptions!$B$35 -> 1200 | G41: =Assumptions!$B$35 -> 1200 | H41: =Assumptions!$B$35 -> 1200 | I41: =Assumptions!$B$35 -> 1200 | ... M41: =Assumptions!$B$35 -> 1200 | N41: =SUM(B41:M41) -> 14400
A42: Marketing / ads | B42: =Assumptions!$B$36 -> 0 | C42: =Assumptions!$B$36 -> 0 | D42: =Assumptions!$B$36 -> 0 | E42: =Assumptions!$B$36 -> 0 | F42: =Assumptions!$B$36 -> 0 | G42: =Assumptions!$B$36 -> 0 | H42: =Assumptions!$B$36 -> 0 | I42: =Assumptions!$B$36 -> 0 | ... M42: =Assumptions!$B$36 -> 0 | N42: =SUM(B42:M42) -> 0
A43: Professional fees | B43: =Assumptions!$B$37 -> 1500 | C43: =Assumptions!$B$37 -> 1500 | D43: =Assumptions!$B$37 -> 1500 | E43: =Assumptions!$B$37 -> 1500 | F43: =Assumptions!$B$37 -> 1500 | G43: =Assumptions!$B$37 -> 1500 | H43: =Assumptions!$B$37 -> 1500 | I43: =Assumptions!$B$37 -> 1500 | ... M43: =Assumptions!$B$37 -> 1500 | N43: =SUM(B43:M43) -> 18000
A44: Bank / card fees | B44: =Assumptions!$B$38 -> 150 | C44: =Assumptions!$B$38 -> 150 | D44: =Assumptions!$B$38 -> 150 | E44: =Assumptions!$B$38 -> 150 | F44: =Assumptions!$B$38 -> 150 | G44: =Assumptions!$B$38 -> 150 | H44: =Assumptions!$B$38 -> 150 | I44: =Assumptions!$B$38 -> 150 | ... M44: =Assumptions!$B$38 -> 150 | N44: =SUM(B44:M44) -> 1800
A45: Insurance | B45: =Assumptions!$B$39 -> 300 | C45: =Assumptions!$B$39 -> 300 | D45: =Assumptions!$B$39 -> 300 | E45: =Assumptions!$B$39 -> 300 | F45: =Assumptions!$B$39 -> 300 | G45: =Assumptions!$B$39 -> 300 | H45: =Assumptions!$B$39 -> 300 | I45: =Assumptions!$B$39 -> 300 | ... M45: =Assumptions!$B$39 -> 300 | N45: =SUM(B45:M45) -> 3600
...

Sheet Cash13Week
A1: 13-Week Direct Cash Flow (rolling) — survival view
A2: Direct method. Recurring items = monthly/4.33; lumpy items (cohort deposits, quarterly tax) are blue inputs placed in the week cash actually lands.
B3: W1 | C3: W2 | D3: W3 | E3: W4 | F3: W5 | G3: W6 | H3: W7 | I3: W8 | J3: W9 | K3: W10 | L3: W11 | M3: W12 | N3: W13
A4: Beginning cash | B4: =Assumptions!$B$43 -> 120000 | C4: =B20 -> 121658.23 | D4: =C20 -> 159316.45 | E4: =D20 -> 160974.68 | F4: =E20 -> 162632.9 | G4: =F20 -> 164291.13 | H4: =G20 -> 165949.35 | I4: =H20 -> 203607.58 | J4: =I20 -> 205265.8 | ... N4: =M20 -> 247898.7
A5: INFLOWS
A6: Subscription collections | B6: =PnL!$B$19/4.33 -> 1063.164 | C6: =PnL!$B$19/4.33 -> 1063.164 | D6: =PnL!$B$19/4.33 -> 1063.164 | E6: =PnL!$B$19/4.33 -> 1063.164 | F6: =PnL!$B$19/4.33 -> 1063.164 | G6: =PnL!$B$19/4.33 -> 1063.164 | H6: =PnL!$B$19/4.33 -> 1063.164 | I6: =PnL!$B$19/4.33 -> 1063.164 | ... N6: =PnL!$B$19/4.33 -> 1063.164
A7: One-time (unlock + flagship) | B7: =(PnL!$B$20+PnL!$B$21)/4.33 -> 2303.0023 | C7: =(PnL!$B$20+PnL!$B$21)/4.33 -> 2303.0023 | D7: =(PnL!$B$20+PnL!$B$21)/4.33 -> 2303.0023 | E7: =(PnL!$B$20+PnL!$B$21)/4.33 -> 2303.0023 | F7: =(PnL!$B$20+PnL!$B$21)/4.33 -> 2303.0023 | G7: =(PnL!$B$20+PnL!$B$21)/4.33 -> 2303.0023 | H7: =(PnL!$B$20+PnL!$B$21)/4.33 -> 2303.0023 | I7: =(PnL!$B$20+PnL!$B$21)/4.33 -> 2303.0023 | ... N7: =(PnL!$B$20+PnL!$B$21)/4.33 -> 2303.0023
A8: Private client collections | B8: =PnL!$B$22/4.33 -> 1212.4711 | C8: =PnL!$B$22/4.33 -> 1212.4711 | D8: =PnL!$B$22/4.33 -> 1212.4711 | E8: =PnL!$B$22/4.33 -> 1212.4711 | F8: =PnL!$B$22/4.33 -> 1212.4711 | G8: =PnL!$B$22/4.33 -> 1212.4711 | H8: =PnL!$B$22/4.33 -> 1212.4711 | I8: =PnL!$B$22/4.33 -> 1212.4711 | ... N8: =PnL!$B$22/4.33 -> 1212.4711
A9: License collections | B9: =(PnL!$B$24+PnL!$B$25)/4.33 -> 0 | C9: =(PnL!$B$24+PnL!$B$25)/4.33 -> 0 | D9: =(PnL!$B$24+PnL!$B$25)/4.33 -> 0 | E9: =(PnL!$B$24+PnL!$B$25)/4.33 -> 0 | F9: =(PnL!$B$24+PnL!$B$25)/4.33 -> 0 | G9: =(PnL!$B$24+PnL!$B$25)/4.33 -> 0 | H9: =(PnL!$B$24+PnL!$B$25)/4.33 -> 0 | I9: =(PnL!$B$24+PnL!$B$25)/4.33 -> 0 | ... N9: =(PnL!$B$24+PnL!$B$25)/4.33 -> 0
A10: B2B cohort deposits (input, lumpy) | B10: 0 | C10: 36000 | D10: 0 | E10: 0 | F10: 0 | G10: 0 | H10: 36000 | I10: 0 | J10: 0 | K10: 0 | L10: 0 | M10: 36000 | N10: 0
A11: Total inflows | B11: =SUM(B6:B10) -> 4578.6374 | C11: =SUM(C6:C10) -> 40578.637 | D11: =SUM(D6:D10) -> 4578.6374 | E11: =SUM(E6:E10) -> 4578.6374 | F11: =SUM(F6:F10) -> 4578.6374 | G11: =SUM(G6:G10) -> 4578.6374 | H11: =SUM(H6:H10) -> 40578.637 | I11: =SUM(I6:I10) -> 4578.6374 | ... N11: =SUM(N6:N10) -> 4578.6374
A12: OUTFLOWS
A13: Payroll | B13: =Assumptions!$B$33*12/52 -> 1384.6154 | C13: =Assumptions!$B$33*12/52 -> 1384.6154 | D13: =Assumptions!$B$33*12/52 -> 1384.6154 | E13: =Assumptions!$B$33*12/52 -> 1384.6154 | F13: =Assumptions!$B$33*12/52 -> 1384.6154 | G13: =Assumptions!$B$33*12/52 -> 1384.6154 | H13: =Assumptions!$B$33*12/52 -> 1384.6154 | I13: =Assumptions!$B$33*12/52 -> 1384.6154 | ... N13: =Assumptions!$B$33*12/52 -> 1384.6154
A14: Contractors | B14: =Assumptions!$B$34/4.33 -> 692.84065 | C14: =Assumptions!$B$34/4.33 -> 692.84065 | D14: =Assumptions!$B$34/4.33 -> 692.84065 | E14: =Assumptions!$B$34/4.33 -> 692.84065 | F14: =Assumptions!$B$34/4.33 -> 692.84065 | G14: =Assumptions!$B$34/4.33 -> 692.84065 | H14: =Assumptions!$B$34/4.33 -> 692.84065 | I14: =Assumptions!$B$34/4.33 -> 692.84065 | ... N14: =Assumptions!$B$34/4.33 -> 692.84065
A15: Software / tools + G&A | B15: =(Assumptions!$B$35+Assumptions!$B$40+Assumptions!$B$38+Assumptions!$B$39)/4.33 -> 496.5358 | C15: =(Assumptions!$B$35+Assumptions!$B$40+Assumptions!$B$38+Assumptions!$B$39)/4.33 -> 496.5358 | D15: =(Assumptions!$B$35+Assumptions!$B$40+Assumptions!$B$38+Assumptions!$B$39)/4.33 -> 496.5358 | E15: =(Assumptions!$B$35+Assumptions!$B$40+Assumptions!$B$38+Assumptions!$B$39)/4.33 -> 496.5358 | F15: =(Assumptions!$B$35+Assumptions!$B$40+Assumptions!$B$38+Assumptions!$B$39)/4.33 -> 496.5358 | G15: =(Assumptions!$B$35+Assumptions!$B$40+Assumptions!$B$38+Assumptions!$B$39)/4.33 -> 496.5358 | H15: =(Assumptions!$B$35+Assumptions!$B$40+Assumptions!$B$38+Assumptions!$B$39)/4.33 -> 496.5358 | I15: =(Assumptions!$B$35+Assumptions!$B$40+Assumptions!$B$38+Assumptions!$B$39)/4.33 -> 496.5358 | ... N15: =(Assumptions!$B$35+Assumptions!$B$40+Assumptions!$B$38+Assumptions!$B$39)/4.33 -> 496.5358
A16: Marketing / ads | B16: =Assumptions!$B$36/4.33 -> 0 | C16: =Assumptions!$B$36/4.33 -> 0 | D16: =Assumptions!$B$36/4.33 -> 0 | E16: =Assumptions!$B$36/4.33 -> 0 | F16: =Assumptions!$B$36/4.33 -> 0 | G16: =Assumptions!$B$36/4.33 -> 0 | H16: =Assumptions!$B$36/4.33 -> 0 | I16: =Assumptions!$B$36/4.33 -> 0 | ... N16: =Assumptions!$B$36/4.33 -> 0
A17: Professional fees (legal/CPA) | B17: =Assumptions!$B$37/4.33 -> 346.42032 | C17: =Assumptions!$B$37/4.33 -> 346.42032 | D17: =Assumptions!$B$37/4.33 -> 346.42032 | E17: =Assumptions!$B$37/4.33 -> 346.42032 | F17: =Assumptions!$B$37/4.33 -> 346.42032 | G17: =Assumptions!$B$37/4.33 -> 346.42032 | H17: =Assumptions!$B$37/4.33 -> 346.42032 | I17: =Assumptions!$B$37/4.33 -> 346.42032 | ... N17: =Assumptions!$B$37/4.33 -> 346.42032
A18: Tax reserve sweep / payment (input) | B18: 0 | C18: 0 | D18: 0 | E18: 0 | F18: 0 | G18: 0 | H18: 0 | I18: 0 | J18: 0 | K18: 0 | L18: 0 | M18: 0 | N18: 9000
A19: Total outflows | B19: =SUM(B13:B18) -> 2920.4122 | C19: =SUM(C13:C18) -> 2920.4122 | D19: =SUM(D13:D18) -> 2920.4122 | E19: =SUM(E13:E18) -> 2920.4122 | F19: =SUM(F13:F18) -> 2920.4122 | G19: =SUM(G13:G18) -> 2920.4122 | H19: =SUM(H13:H18) -> 2920.4122 | I19: =SUM(I13:I18) -> 2920.4122 | ... N19: =SUM(N13:N18) -> 11920.412
A20: Ending cash | B20: =B4+B11-B19 -> 121658.23 | C20: =C4+C11-C19 -> 159316.45 | D20: =D4+D11-D19 -> 160974.68 | E20: =E4+E11-E19 -> 162632.9 | F20: =F4+F11-F19 -> 164291.13 | G20: =G4+G11-G19 -> 165949.35 | H20: =H4+H11-H19 -> 203607.58 | I20: =I4+I11-I19 -> 205265.8 | ... N20: =N4+N11-N19 -> 240556.93
A21: Net change | B21: =B11-B19 -> 1658.2253 | C21: =C11-C19 -> 37658.225 | D21: =D11-D19 -> 1658.2253 | E21: =E11-E19 -> 1658.2253 | F21: =F11-F19 -> 1658.2253 | G21: =G11-G19 -> 1658.2253 | H21: =H11-H19 -> 37658.225 | I21: =I11-I19 -> 1658.2253 | ... N21: =N11-N19 -> -7341.7747
A23: Lowest weekly ending cash (13wk): | C23: =MIN(B20:N20) -> 121658.23

Sheet Runway
A1: Cash & Runway
A3: Current cash | B3: =Assumptions!$B$43 -> 120000
A4: Avg monthly EBITDA (M1–M3) | B4: =AVERAGE(PnL!B48:D48) -> 9387.2177
A5: Avg monthly net burn | B5: =MAX(0,-B4) -> 0
A6: Runway (months) | B6: =IF(B5=0,"cash-flow positive",B3/B5) -> cash-flow positive
A7: Full-year EBITDA (M1–M12) | B7: =PnL!N48 -> 516017.61
A9: QUICK SENSITIVITY — Year 1 (revenue flex, costs held)
A10: Scenario | B10: Revenue | C10: Total cost | D10: EBITDA | E10: Ending cash
A11: Worst (-20%) | B11: =PnL!$N$26*0.8 -> 800966.86 | C11: =PnL!$N$34+PnL!$N$47 -> 485190.96 | D11: =B11-C11 -> 315775.89 | E11: =Assumptions!$B$43+D11 -> 435775.89
A12: Base | B12: =PnL!$N$26*1 -> 1001208.6 | C12: =PnL!$N$34+PnL!$N$47 -> 485190.96 | D12: =B12-C12 -> 516017.61 | E12: =Assumptions!$B$43+D12 -> 636017.61
A13: Best (+20%) | B13: =PnL!$N$26*1.2 -> 1201450.3 | C13: =PnL!$N$34+PnL!$N$47 -> 485190.96 | D13: =B13-C13 -> 716259.32 | E13: =Assumptions!$B$43+D13 -> 836259.32
A15: Runway is a decision instrument, not a filing. Tax positions (reserve %, nexus, R&D) need CPA review. No cash moves without approval.
